2021-03-28 00:22:59,460 INFO    MainThread:9304 [internal.py:wandb_internal():88] W&B internal server running at pid: 9304, started at: 2021-03-28 00:22:59.452882
2021-03-28 00:22:59,463 INFO    WriterThread:9304 [datastore.py:open_for_write():77] open: C:\Users\pnk72\Downloads\CDGI-project\wandb\run-20210328_002254-36pw8qt5\run-36pw8qt5.wandb
2021-03-28 00:22:59,464 DEBUG   HandlerThread:9304 [handler.py:handle_request():120] handle_request: check_version
2021-03-28 00:22:59,470 DEBUG   SenderThread:9304 [sender.py:send():160] send: header
2021-03-28 00:22:59,470 DEBUG   SenderThread:9304 [sender.py:send():160] send: request
2021-03-28 00:22:59,470 DEBUG   SenderThread:9304 [sender.py:send_request():169] send_request: check_version
2021-03-28 00:22:59,548 DEBUG   SenderThread:9304 [sender.py:send():160] send: run
2021-03-28 00:22:59,785 ERROR   SenderThread:9304 [internal_api.py:execute():126] 403 response executing GraphQL.
2021-03-28 00:22:59,786 ERROR   SenderThread:9304 [internal_api.py:execute():127] {"errors":[{"message":"permission denied","path":["upsertBucket"],"extensions":{"code":"PERMISSION_ERROR"}}],"data":{"upsertBucket":null}}
2021-03-28 00:23:00,548 INFO    HandlerThread:9304 [handler.py:finish():624] shutting down handler
2021-03-28 00:23:00,548 INFO    WriterThread:9304 [datastore.py:close():258] close: C:\Users\pnk72\Downloads\CDGI-project\wandb\run-20210328_002254-36pw8qt5\run-36pw8qt5.wandb
2021-03-28 00:23:00,549 ERROR   MainThread:9304 [internal.py:wandb_internal():158] Thread SenderThread:
Traceback (most recent call last):
  File "C:\Users\pnk72\Anaconda3\envs\cgdi\lib\site-packages\wandb\old\retry.py", line 96, in __call__
    result = self._call_fn(*args, **kwargs)
  File "C:\Users\pnk72\Anaconda3\envs\cgdi\lib\site-packages\wandb\sdk\internal\internal_api.py", line 129, in execute
    six.reraise(*sys.exc_info())
  File "C:\Users\pnk72\Anaconda3\envs\cgdi\lib\site-packages\six.py", line 703, in reraise
    raise value
  File "C:\Users\pnk72\Anaconda3\envs\cgdi\lib\site-packages\wandb\sdk\internal\internal_api.py", line 123, in execute
    return self.client.execute(*args, **kwargs)
  File "C:\Users\pnk72\Anaconda3\envs\cgdi\lib\site-packages\wandb\vendor\gql-0.2.0\gql\client.py", line 52, in execute
    result = self._get_result(document, *args, **kwargs)
  File "C:\Users\pnk72\Anaconda3\envs\cgdi\lib\site-packages\wandb\vendor\gql-0.2.0\gql\client.py", line 60, in _get_result
    return self.transport.execute(document, *args, **kwargs)
  File "C:\Users\pnk72\Anaconda3\envs\cgdi\lib\site-packages\wandb\vendor\gql-0.2.0\gql\transport\requests.py", line 39, in execute
    request.raise_for_status()
  File "C:\Users\pnk72\Anaconda3\envs\cgdi\lib\site-packages\requests\models.py", line 943, in raise_for_status
    raise HTTPError(http_error_msg, response=self)
requests.exceptions.HTTPError: 403 Client Error: Forbidden for url: https://api.wandb.ai/graphql

During handling of the above exception, another exception occurred:

Traceback (most recent call last):
  File "C:\Users\pnk72\Anaconda3\envs\cgdi\lib\site-packages\wandb\apis\normalize.py", line 24, in wrapper
    return func(*args, **kwargs)
  File "C:\Users\pnk72\Anaconda3\envs\cgdi\lib\site-packages\wandb\sdk\internal\internal_api.py", line 883, in upsert_run
    response = self.gql(mutation, variable_values=variable_values, **kwargs)
  File "C:\Users\pnk72\Anaconda3\envs\cgdi\lib\site-packages\wandb\old\retry.py", line 105, in __call__
    if not check_retry_fn(e):
  File "C:\Users\pnk72\Anaconda3\envs\cgdi\lib\site-packages\wandb\util.py", line 713, in no_retry_auth
    raise CommError("Permission denied, ask the project owner to grant you access")
wandb.errors.CommError: Permission denied, ask the project owner to grant you access

During handling of the above exception, another exception occurred:

Traceback (most recent call last):
  File "C:\Users\pnk72\Anaconda3\envs\cgdi\lib\site-packages\wandb\sdk\internal\internal_util.py", line 54, in run
    self._run()
  File "C:\Users\pnk72\Anaconda3\envs\cgdi\lib\site-packages\wandb\sdk\internal\internal_util.py", line 95, in _run
    self._process(record)
  File "C:\Users\pnk72\Anaconda3\envs\cgdi\lib\site-packages\wandb\sdk\internal\internal.py", line 279, in _process
    self._sm.send(record)
  File "C:\Users\pnk72\Anaconda3\envs\cgdi\lib\site-packages\wandb\sdk\internal\sender.py", line 162, in send
    send_handler(record)
  File "C:\Users\pnk72\Anaconda3\envs\cgdi\lib\site-packages\wandb\sdk\internal\sender.py", line 541, in send_run
    self._init_run(run, config_value_dict)
  File "C:\Users\pnk72\Anaconda3\envs\cgdi\lib\site-packages\wandb\sdk\internal\sender.py", line 563, in _init_run
    server_run, inserted = self._api.upsert_run(
  File "C:\Users\pnk72\Anaconda3\envs\cgdi\lib\site-packages\wandb\apis\normalize.py", line 62, in wrapper
    six.reraise(CommError, CommError(message, err), sys.exc_info()[2])
  File "C:\Users\pnk72\Anaconda3\envs\cgdi\lib\site-packages\six.py", line 702, in reraise
    raise value.with_traceback(tb)
  File "C:\Users\pnk72\Anaconda3\envs\cgdi\lib\site-packages\wandb\apis\normalize.py", line 24, in wrapper
    return func(*args, **kwargs)
  File "C:\Users\pnk72\Anaconda3\envs\cgdi\lib\site-packages\wandb\sdk\internal\internal_api.py", line 883, in upsert_run
    response = self.gql(mutation, variable_values=variable_values, **kwargs)
  File "C:\Users\pnk72\Anaconda3\envs\cgdi\lib\site-packages\wandb\old\retry.py", line 105, in __call__
    if not check_retry_fn(e):
  File "C:\Users\pnk72\Anaconda3\envs\cgdi\lib\site-packages\wandb\util.py", line 713, in no_retry_auth
    raise CommError("Permission denied, ask the project owner to grant you access")
wandb.errors.CommError: Permission denied, ask the project owner to grant you access
2021-03-28 00:23:02,595 INFO    MainThread:9304 [internal.py:handle_exit():78] Internal process exited
